Workbook

Sheet Sheet1
A1: Platform | B1: ProductID | C1: ProductName | D1: URL | E1: SKUsToScrape | F1: 多多百补商品
A2: 京东 | B2: 6923185654865 | C2: 云米 AI净水器小海豚2 | D2: https://item.jd.com/10176566189735.html | F2: 是
A3: 京东 | B3: 6923185654865 | C3: 云米 AI净水器小海豚2 | D3: https://item.jd.com/10183913655778.html | F3: 是
A4: 京东 | B4: 6923185654865 | C4: 云米 AI净水器小海豚2 | D4: https://item.jd.com/10176929301628.html | F4: 是
A5: 京东 | B5: 6923185654865 | C5: 云米 AI净水器小海豚2 | D5: https://item.jd.com/10183906956002.html | F5: 是
A6: 京东 | B6: 6923185654865 | C6: 云米 AI净水器小海豚2 | D6: https://item.jd.com/10175706195522.html | F6: 是
A7: 京东 | B7: 6923185654865 | C7: 云米 AI净水器小海豚2 | D7: https://item.jd.com/10160574648642.html | F7: 是
A8: 京东 | B8: 6923185654865 | C8: 云米 AI净水器小海豚2 | D8: https://item.jd.com/10154923901427.html | F8: 是
A9: 京东 | B9: 6923185653684 | C9: 云米AI净水器小海豚600G+ | D9: https://item.jd.com/10176532354348.html | F9: 是
A10: 京东 | B10: 6923185653684 | C10: 云米AI净水器小海豚600G+ | D10: https://item.jd.com/10167658224082.html | F10: 是
A11: 京东 | B11: 6923185653684 | C11: 云米AI净水器小海豚600G+ | D11: https://item.jd.com/10176559768031.html | F11: 是
A12: 京东 | B12: 6923185653684 | C12: 云米AI净水器小海豚600G+ | D12: https://item.jd.com/10176532354349.html | F12: 是
A13: 京东 | B13: 6923185653684 | C13: 云米AI净水器小海豚600G+ | D13: https://item.jd.com/10151813991756.html | F13: 是
... A36: 淘系 | B36: 6923185654865 | C36: 云米 AI净水器小海豚2 | D36: https://item.taobao.com/item.htm?id=968133433761 | F36: 是
A37: 淘系 | B37: 6923185615415 | C37: AI净饮机Super2 | D37: https://item.taobao.com/item.htm?id=902116631708
A38: 京东 | B38: 6923185653981 | C38: AI净水器Super2Y1200G | D38: https://item.jd.com/100113886253.html
A39: 淘系 | B39: 6923185653981 | C39: AI净水器Super2Y1200G | D39: https://item.taobao.com/item.htm?id=671890389960
A40: 京东 | B40: 6923185615415 | C40: AI净饮机Super2 | D40: https://item.taobao.com/item.htm?id=100193748406
A41: 淘系 | B41: 6923185615415 | C41: AI净饮机Super2 | D41: https://detail.tmall.com/item.htm?id=902116631708

Sheet 店铺表2
A1: 排序 | B1: 商品名称 | C1: 别名 | D1: 商品ID | E1: 商品编码 | F1: 活动id | G1: 资源位 | H1: 价格(元) | I1: 总库存 | J1: 收藏数 | K1: 累计销量 | L1: 30日销量 | M1: 商品体检分 | N1: 创建时间 | O1: 品类 | P1: 链接
B2: 云米澎湃家用净水器1000G厨房过滤器饮水机RO反渗透纯水机直饮机 | C2: 1000G | D2: 324013287297
B3: 云米净水器家用直饮加热一体机RO反渗透1键即热纯水机母婴1000G | C3: 1000G | D3: 324556108932
B4: 云米净水器套装澎湃1000G家用厨房过滤器纯水机直饮机5年长效RO膜 | C4: 1000G | D4: 339695819374
B5: 云米净水器家用厨下式原厂 零陈水反渗透纯水机水博士1000G正品 | C5: 1000G | D5: 403155215848
B6: 云米(VIOMI) 小云米净水器Super、Vision1000G/1200G复合滤芯 | C6: 1000G | D6: 433791622833
B7: 净水器家用厨下净水机 零陈水反渗透纯水机大流量1000G智能直饮机 | C7: 1000G | D7: 475210055336
B8: 云米净水器家用厨下净水机 零陈水净化反渗透纯水机1000G直饮机 | C8: 1000G | D8: 475213920815
B9: [政府补贴20%]云米净水器900G双出水家用直饮RO反渗透过滤1000G | C9: 1000G | D9: 517447238153
B10: [政府补贴20%]云米澎湃1000G净水器双出水反渗透RO厨下式家用直饮 | C10: 1000G | D10: 579997893702
B11: 云米净水器家用净水机1000G 6年RO反渗透大通量 厨下直饮鲜活水 | C11: 1000G | D11: 585484005023
B12: 云米澎湃1000G双出水净水器5年RO反渗透厨房过滤器 | C12: 1000G | D12: 587781919045
B13: 云米1000G双出水净水器前置过滤器两件套全屋过滤RO反渗透大通量 | C13: 1000G | D13: 588093744579
... B53: 云米净水器厨下纯水机反渗透RO机家用大通量净水机Super Pro1200G | C53: 1200G | D53: 351897325475
B54: 云米净水器家用直饮ro反渗透SuperY 1200G管线机前置过滤器套装 | C54: 1200G | D54: 534931901352 | E54: 6923185619796,6923185650058
B55: 云米净水器家用1200G厨下式直饮机RO反渗透纯水机过滤器Super 2 | C55: 1200G | D55: 536574926395
B56: 云米净水器双出水Super 2 1200G母婴直饮RO反渗透纯水机过滤0陈水 | C56: 1200G | D56: 557294936690
B57: 云米净水器1200G直饮净水器厨房RO反渗透净水机家用大通量双RO | C57: 1200G | D57: 574235957377
B58: 云米净水器1200G双出水0陈水1200G反渗透RO厨下式家用Super2Max | C58: 1200G | D58: 576428340757
B59: 云米1200G双出水净水器全自动前置过滤器冷热管线机三件套装6年RO | C59: 1200G | D59: 586921930445
B60: 云米1200G双出水净水器厨下式6年RO反渗透Super 2纯水机触控厨房 | C60: 1200G | D60: 587894489367
A61: 146 | B61: 云米净水器1200G昆仑矿泉8年RO反渗透双出水直饮机厨下式净饮机 | C61: 1200G | D61: 598235047829
B62: 云米净水器1200G大通量+家用直饮水机管线机壁挂式加热直饮一体机 | C62: 1200G | D62: 633248334419
B63: 云米净水器1200G大通量+家用直饮水机管线机壁挂式加热直饮一体机 | C63: 1200G | D63: 633255566536
B64: 云米鲜活泉1200G双出水纯天然净水器直饮0零陈水母婴一级Super 2Y | C64: 1200G | D64: 635155374997
B65: 云米鲜活泉1200G双出水纯天然净水器家用直饮零陈水母婴Super 2Y | C65: 1200G | D65: 635161525233
B66: 云米家用反渗透净水器1200G直饮净水过滤器即热管线机饮水机套装 | C66: 1200G | D66: 644460564363
B67: 云米鲜活泉1200G双出水RO反渗透直饮APP母婴净水器管线机两件套装 | C67: 1200G | D67: 665884863038
B68: 云米昆仑矿泉净水器家用直饮1200G大通量RO反渗透净饮机母婴直饮 | C68: 1200G | D68: 684109870392
B69: 云米鲜活泉1200G双出水纯天然净水器直饮RO反渗透纯水Super 2Y | C69: 1200G | D69: 698973724674
B70: 云米昆仑1200G净水器家用厨下式直饮过滤器RO反渗透母婴净水机 | C70: 1200G | D70: 701581276222
B71: 云米鲜活泉1200G双出水纯天然净水器家用直饮纯水母婴Super 2Y | C71: 1200G | D71: 703282113561
B72: 云米鲜活泉1200G双出水纯天然净水器家用直饮纯水母婴Super 2Y | C72: 1200G | D72: 708510913081
B73: 云米净水器母婴级直饮鲜活泉1200G家用厨下式ro反渗透0陈水净水机 | C73: 1200G | D73: 748920157650
... B76: 云米净水器家用昆仑4弱碱矿泉1200G净矿8年RO反渗透矿物质直饮 | C76: 1200G | D76: 780695900762
C77: 1200G | D77: 540840221349
B78: 云米净水器家用昆仑4Pro弱碱矿泉1400G净矿8年RO反渗透直饮机厨下 | C78: 1400G | D78: 780676442407
B79: 云米净水器家用昆仑4Pro弱碱矿泉1400G净矿8年RO反渗透直饮机厨下 | C79: 1400G | D79: 780693742114
A80: 150 | B80: 焕新云米1S管线机壁挂式饮水机即热式直饮智控APP净水器UV紫外线 | C80: 1S管线机 | D80: 820207679318
B81: 云米1S管线机壁挂式饮水机即热式直饮智控APP净水器伴侣UV紫外线 | C81: 1S管线机 | D81: 825465416773
...

Sheet 店铺表3
A1: 序号 | B1: 店铺 | C1: 备注 | D1: 百亿链接
A2: 1 | B2: 云米电器官方旗舰店 | C2: 官旗（自营） | D2: 7
A3: 2 | B3: 云米智能电器旗舰店 | C3: 智能（深圳易兔） | D3: 4
A4: 3 | B4: 云米净水设备旗舰店 | C4: 净水（佛山臻兴） | D4: 7
A5: 4 | B5: 云米净饮水旗舰店 | C5: 净饮（北京汇美） | D5: 3
A6: 5 | B6: 云米电器旗舰店 | C6: 电器（佛山优豆） | D6: 0
A7: 6 | B7: 云米全屋净水器旗舰店 | C7: 全屋（深圳易兔） | D7: 3 | I7: 维度 | J7: ① 自营官方旗舰店 (主阵地) | K7: ② 自营品类旗舰店 (突击队) | L7: ③ 其他旗舰店 (游击队)
A8: 7 | B8: 云米生活电器旗舰店 | C8: 生活（河北美承） | D8: 6 | I8: 店铺定位 | J8: 【品牌树立 + 价格标杆】 | K8: 【极致单品 + 流量收割】 | L8: 【差异化组套 + 收割心理】
A9: 8 | B9: 云米净水电器旗舰店 | C9: 天津匠心 | D9: 0 | J9: 代表品牌官方形象，建立用户信任，承接搜索品牌词的流量。 | K9: 专为499爆品而生，不做杂七杂八，店铺权重极度垂直，效率最高。 | L9: 主打“工厂直营”或“特卖”心智，用不同的SKU组合拦截长尾流量。
A10: 9 | B10: 云米净水滤芯官方旗舰店 | C10: 天津园迈 | D10: 0 | I10: GMV目标 | J10: 50% (稳扎稳打) | K10: 30% (激进冲锋) | L10: 20% (查漏补缺)
A11: 10 | B11: 云米净水器耗材旗舰店 | C11: 北京星途 | D11: 0 | I11: 产品矩阵 | J11: 【全产品线覆盖：树立品牌形象 1. 引流款： 小海豚3-600G (499元) 2. 改善款： Super Pro 1000G、1200G鲜活泉、即热款。 3. 全家桶： 全系管线机、台净、滤芯。 策略： 只有这里能买到最全的型号，承接所有高端需求。 | K11: 【聚焦“小海豚”性价比系列】 1. 核心爆款： 小海豚3-600G (499元) (占比80%) 2. 升杯款： 小海豚2-1000G、待定小海豚3-1000G。 策略： 砍掉1000元以上的高端机和管线机，只卖千元内的极致性价比款，确保人群标签极度精准。 | L11: 【差异化/套装/新品测试】 1. 套购组合： “净水器+管线机”套装，“净水器+3年滤芯”套装。 2. 细分品类： 重点推AI管线机系列、台净入口机。 3. 差异化新品： 承接26年上市的 Pro系列 (600-Pro/1000-Pro)，与主店的标准版做区分。
I12: 链接数量 | J12: 30个常规链接+20个百亿补贴链接 | K12: 5个常规链接+2个百亿链接 | L12: 50个常规链接+30个百亿补贴链接
I13: 499策略 | J13: 策略：正规军打法 | K13: 策略：爆款打法 | L13: 策略：差异化打法
I14: (同款不同法) | J14: · 上架标准版链接。 | K14: · 复制链接： 换一套主图和标题，上架同样的499产品。 | L14: · 防比价： 不直接挂499，而是挂“499+赠品”或“多滤芯套餐”。
J15: · 主图强调：品牌、售后、官方正品。 | K15: · 视觉差异： 主图用“暴力拆机”、“工厂流水线”等更接地气的素材。 | L15: · 改规格： 比如主推“租房版”、“公寓版”，其实机器一样，但场景词不同。
J16: · 占据“百亿补贴”主坑位。 | K16: · 活动冲锋： 激进报名万人团、秒杀，敢于亏损冲量。
I17: 运营动作 | J17: 保 DSR + 做服务 | K17: 全站推广 + 暴力获客 | L17: 自然流 + 捡漏
J18: · 确保评分4.8+，作为品牌脸面。 | K18: · 预算倾斜，全站推广火力全开。 | L18: · 蹭主店流量，做推荐流量。
J19: · 承接对服务要求高的“挑剔客户”。 | K19: · 客服话术更直接：“就是便宜，买到赚到”。 | L19: · 承接那些觉得“旗舰店滤芯太贵”想找便宜的用户。
I20: 开店节奏 | J20: / | K20: 2025年12月完成1店、2026年3月完成1店 | L20: /
I21: 店铺数量 | J21: 1 | K21: 2 | L21: 10
G31: 1.5
G32: 1.5
G33: 1.5
G34: 1.5
G35: 1.5
G36: =G35*G34*G33*G32*G31 -> 7.59375

Sheet 监控表副本
A1: Platform | B1: ProductID | C1: ProductName | D1: URL | E1: SKUsToScrape | F1: 多多百补商品
A2: 京东 | B2: 6923185615415 | C2: 云米AI净饮机Super 2 | D2: https://item.jd.com/100193748406.html
A3: 京东 | B3: 6923185655794 | C3: 云米AI冷热管线机Super2 Pro | D3: https://item.jd.com/100216835595.html
A4: 京东 | B4: 6923185655794 | C4: 云米AI冷热管线机Super2 Pro | D4: https://item.jd.com/10190163229722.html
A5: 京东 | B5: 6923185655794 | C5: 云米AI冷热管线机Super2 Pro | D5: https://item.jd.com/10190186867694.html
A6: 京东 | B6: 6923185615415 | C6: 云米AI净饮机Super 2 | D6: https://item.jd.com/10190216497508.html
A7: 京东 | B7: 6923185680772 | C7: 云米净水器前置颗粒活性炭滤芯 | D7: https://item.jd.com/10191186064455.html
A8: 京东 | B8: 6923185600190 | C8: 云米净水器PP棉滤芯 | D8: https://item.jd.com/10191186064454.html
A9: 京东 | B9: 6923185600121 | C9: 云米净水器后置炭棒滤芯 | D9: https://item.jd.com/10191186064456.html
A10: 京东 | B10: 6923185653998 | C10: 复合滤芯 | D10: https://item.jd.com/10182080183404.html
A11: 京东 | B11: 6923185654254 | C11: 云米AI昆仑矿泉净水机 Super 2E 2500 | D11: https://item.jd.com/10140536700853.html
A12: 京东 | B12: S2503111808001 | C12: 小海豚净水器+Super2E管线机 | D12: https://item.jd.com/10143995938099.html
A13: 京东 | B13: S2503111807001 | C13: 小海豚1000G+Master 2S管线机 | D13: https://item.jd.com/10143995938098.html
... A53: 京东 | B53: 6923185651116 | C53: 云米·泉先AI即热净水器 Super Pro 1000G(升级) | D53: https://item.jd.com/100054671477.html

Sheet ACT
A1: 活动id | B1: 可报名 | C1: 小二说明 | D1: 门槛要求 | E1: 活动名称 | F1: 活动类型
A2: 22773 | B2: https://mms.pinduoduo.com/act/detail?id=22773 | C2: 非超星星报名： | D2: 百亿补贴报名入口-政府补贴专用 | E2: 百亿补贴报名入口-政府补贴专用 | F2: 百亿补贴
A3: 23550 | B3: https://mms.pinduoduo.com/act/detail?id=23550 | C3: 95折百亿有官补品入口 | D3: 竞价官补不可报名 | E3: 百亿加倍补-平台重点补贴商单件折扣报名 | F3: 百亿补贴
A4: 22180 | B4: https://mms.pinduoduo.com/act/detail?id=22180 | C4: 9折百亿非官补品入口 | D4: 日销需＞1500元 | E4: =VLOOKUP($A4,'[1]拼多多活动报名记录_2025-10-13-02-04-31'!$J:$L,2,0) -> 百亿加倍补-电器大爆款报名 | F4: =VLOOKUP($A4,'[1]拼多多活动报名记录_2025-10-13-02-04-31'!$J:$L,3,0) -> 百亿补贴
A5: 22148 | B5: https://mms.pinduoduo.com/act/detail?id=22148 | E5: =VLOOKUP($A5,'[1]拼多多活动报名记录_2025-10-13-02-04-31'!$J:$L,2,0) -> 百亿补贴-百亿加倍补-特定商品报名链接 | F5: =VLOOKUP($A5,'[1]拼多多活动报名记录_2025-10-13-02-04-31'!$J:$L,3,0) -> 百亿补贴
A6: 10441 | B6: https://mms.pinduoduo.com/act/detail?id=10441 | E6: =VLOOKUP($A6,'[1]拼多多活动报名记录_2025-10-13-02-04-31'!$J:$L,2,0) -> 百亿补贴报名入口 | F6: =VLOOKUP($A6,'[1]拼多多活动报名记录_2025-10-13-02-04-31'!$J:$L,3,0) -> 百亿补贴
A7: 23581 | B7: https://mms.pinduoduo.com/act/detail?id=23581 | E7: =VLOOKUP($A7,'[1]拼多多活动报名记录_2025-10-13-02-04-31'!$J:$L,2,0) -> 百亿补贴报名入口-全国活动 | F7: =VLOOKUP($A7,'[1]拼多多活动报名记录_2025-10-13-02-04-31'!$J:$L,3,0) -> 百亿补贴
A8: 22827 | B8: https://mms.pinduoduo.com/act/detail?id=22827 | C8: 快速审核报名： | E8: =VLOOKUP($A8,'[1]拼多多活动报名记录_2025-10-13-02-04-31'!$J:$L,2,0) -> 百亿补贴报名入口-政府补贴（快速通道） | F8: =VLOOKUP($A8,'[1]拼多多活动报名记录_2025-10-13-02-04-31'!$J:$L,3,0) -> 百亿补贴
A9: 22181 | B9: https://mms.pinduoduo.com/act/detail?id=22181 | C9: 8折百亿非官补品入口 | E9: =VLOOKUP($A9,'[1]拼多多活动报名记录_2025-10-13-02-04-31'!$J:$L,2,0) -> 百亿加倍补-电器非爆款报名 | F9: =VLOOKUP($A9,'[1]拼多多活动报名记录_2025-10-13-02-04-31'!$J:$L,3,0) -> 百亿补贴
B10: https://mms.pinduoduo.com/act/hot-goods | C10: 秒杀活动-百万爆款： | D10: 日销<1000元的报名 | E10: 百万爆款 | F10: 爆款计划
A11: 18056 | B11: https://mms.pinduoduo.com/act/detail?id=18056 | C11: 百亿官补： | D11: 日销＞1w元 | E11: =VLOOKUP($A11,'[1]拼多多活动报名记录_2025-10-13-02-04-31'!$J:$L,2,0) -> 【平台官补】补贴秒杀品牌千万爆款团 | F11: =VLOOKUP($A11,'[1]拼多多活动报名记录_2025-10-13-02-04-31'!$J:$L,3,0) -> 补贴秒杀
A12: 19161 | B12: https://mms.pinduoduo.com/act/detail?id=19161 | C12: 百亿在线： | D12: 日销＞1w元 | E12: 【千万爆款团】补贴秒杀品牌自补 | F12: 补贴秒杀
A13: 20981 | B13: https://mms.pinduoduo.com/act/detail?id=20981 | E13: =VLOOKUP($A13,'[1]拼多多活动报名记录_2025-10-13-02-04-31'!$J:$L,2,0) -> 【10周年庆】20981长期报名入口 | F13: =VLOOKUP($A13,'[1]拼多多活动报名记录_2025-10-13-02-04-31'!$J:$L,3,0) -> 大促搜索池
A14: 23620 | B14: https://mms.pinduoduo.com/act/detail?id=23620 | C14: 大促搜索池 | E14: =VLOOKUP($A14,'[1]拼多多活动报名记录_2025-10-13-02-04-31'!$J:$L,2,0) -> 【10周年庆】-国庆中秋搜索推荐报名专区 | F14: =VLOOKUP($A14,'[1]拼多多活动报名记录_2025-10-13-02-04-31'!$J:$L,3,0) -> 大促搜索池
A15: 23149 | B15: https://mms.pinduoduo.com/act/detail?id=23149 | E15: =VLOOKUP($A15,'[1]拼多多活动报名记录_2025-10-13-02-04-31'!$J:$L,2,0) -> 平台官方活动-长期-搜索推荐专区 | F15: =VLOOKUP($A15,'[1]拼多多活动报名记录_2025-10-13-02-04-31'!$J:$L,3,0) -> 大促搜索池
A16: 22704 | B16: https://mms.pinduoduo.com/act/detail?id=22704 | E16: 【百亿消费券】单件折扣9.7折 | F16: 品牌清仓
A17: 21663 | B17: https://mms.pinduoduo.com/act/detail?id=21663 | E17: =VLOOKUP($A17,'[1]拼多多活动报名记录_2025-10-13-02-04-31'!$J:$L,2,0) -> 【百亿消费券】单件折扣9折 | F17: =VLOOKUP($A17,'[1]拼多多活动报名记录_2025-10-13-02-04-31'!$J:$L,3,0) -> 品牌清仓
A18: 21657 | B18: https://mms.pinduoduo.com/act/detail?id=21657 | E18: =VLOOKUP($A18,'[1]拼多多活动报名记录_2025-10-13-02-04-31'!$J:$L,2,0) -> 【百亿消费券】活动长期报名链接 | F18: =VLOOKUP($A18,'[1]拼多多活动报名记录_2025-10-13-02-04-31'!$J:$L,3,0) -> 品牌清仓
A19: 21967 | B19: https://mms.pinduoduo.com/act/detail?id=21967 | E19: =VLOOKUP($A19,'[1]拼多多活动报名记录_2025-10-13-02-04-31'!$J:$L,2,0) -> 【上首页】流量续航（极速审核） | F19: =VLOOKUP($A19,'[1]拼多多活动报名记录_2025-10-13-02-04-31'!$J:$L,3,0) -> 首页推荐专区
A20: 4534 | B20: https://mms.pinduoduo.com/act/detail?id=4534 | C20: 补贴万人团 | D20: 该入口每天坑位有限，报名后找小二催审 | E20: 【万人团】秒杀普通商品 | F20: 万人团秒杀
A21: 17480 | B21: https://mms.pinduoduo.com/act/detail?id=17480 | C21: 非百亿在线： | D21: 日销＞1w元 | E21: 【千万爆款团】限时秒杀 | F21: 万人团秒杀
A22: 22660 | B22: https://mms.pinduoduo.com/act/detail?id=22660 | C22: 秒杀活动-免审通道： | D22: 日销<1000元的报名 | E22: 【免审】限时秒杀外场通道 | F22: 限时秒杀
A23: 584 | B23: https://mms.pinduoduo.com/act/detail?id=584 | C23: 通天塔、单坑 | D23: 日销＞1500元的报名,8折-9折 | E23: 【精选首页】限时秒杀 | F23: 限时秒杀
A24: 20453
A25: 23531

Sheet products1
A1: 序号 | B1: 别名 | C1: 商品ID | D1: 69码 | E1: 平台ID | F1: 物料编码 | G1: 券前价(元) | H1: 活动类型 | I1: 标准名称 | J1: 标注型号
A2: 1 | B2: 小海豚600G+（老） | C2: 225501370546 | D2: 6923185653684 | E2: 1600502140541 | F2: 10.01.01.01.0174 | G2: 559 | H2: 百亿补贴，叠加千万爆款团活动。平台券38元，最低559 | I2: 云米AI净水器小海豚600G+ | J2: MR662-E
A3: 2 | B3: 前置super | C3: 573873753845 | D3: 6923185649885 | E3: 1537803249260 | F3: 10.01.01.05.0027 | G3: 599 | H3: 净饮水店百亿，457.66 | I3: 云米·泉先前置过滤器 Super | J3: VF4-A
A4: 3 | B4: 小海豚600G+（新） | C4: 819506595979 | D4: 6923185653684 | E4: 1787046011387 | F4: 10.01.01.01.0174 | G4: 599 | H4: 百亿补贴，749*0.8=599，京东最低575.28 | I4: 云米AI净水器小海豚600G+ | J4: MR662-E
A5: 4 | B5: 蓝泽800G+（新） | C5: 837957770723 | D5: 6923185653974 | E5: 1800120524656 | F5: 10.01.01.01.0180 | G5: 699 | H5: 京东639，P图款，758重新报名百亿,报不上了，以前799都能上都能卖，现在要求611 | I5: 云米AI净水器小白龙800G+ | J5: MR862-C
A6: 5 | B6: 小海豚600G+6年套装 | C6: 852161740747 | D6: S2508151538001 | E6: 1812658223669 | G6: 759 | H6: 未定价，百亿抓价到639，没办法做 | I6: 云米AI净水器小海豚600G+，复合滤芯X2 | J6: MR662-E
A7: 6 | B7: 小竹泉1000G | C7: 842195971715 | D7: 6923185654247 | E7: 1803617356458 | F7: 10.01.01.01.0183 | G7: 799 | H7: 866,平台补61元，到手805元，799，京东971, 平台补43.88 | I7: 云米AI净水器Smart 1000G | J7: MR1072
A8: 7 | B8: 小海豚2 1000G （新A) | C8: 205458105137 | D8: 6923185654865 | E8: 1640308935573 | F8: 10.01.01.01.0197 | G8: 899 | H8: 899，百亿补贴+官补，官补审核中，过了记得把首件优惠去掉 | I8: 云米 AI净水器小海豚2 | J8: MR1021
A9: 12 | B9: 即热管线机Master2S | C9: 604410073495 | D9: 6923185652526 | E9: 1584984425232 | F9: 10.01.01.10.0011 | G9: 1374 | H9: 京东投诉，全屋净水（易兔），自补后764，京东764.23 | I9: 云米·泉先AI管线机Master2S | J9: MG6-A
A10: 9 | B10: 现货泉 2Y | C10: 849000374681 | D10: 6923185653981 | E10: 1809523164736 | F10: 10.01.01.01.0181 | G10: 1199 | H10: 百亿掉线，京东1132，天猫1199，价格表是1198，京东1158，跟价，上涨20 | I10: 云米AI净水器Super 2Y 1200G | J10: MR10102-A
A11: 10 | B11: 小蓝调600G | C11: 850883552953 | D11: 6923185653592 | E11: 1811278299045 | F11: 10.01.01.01.0170 | G11: 1299 | H11: 京东579，新链接培养试试,比价了，做不了 | I11: 云米·泉先AI净水器蓝调 600G+ | J11: MR662-D
A12: 8 | B12: 冷热双出水管线机Super2E | C12: 861508688697 | D12: 6923185650966 | E12: 1584984425232 | F12: 10.01.01.04.0004 | G12: 1175 | H12: 净饮水（汇美）自补后851.7，京东993.73，917，可以做到1019 | I12: 云米·泉先 AI冷热管线机 Super 2E | J12: MG5D-A
A13: 18 | B13: 两件套1000G+管线机2E | C13: 846750208008 | D13: S2503111807001 | E13: 1807613941477 | G13: 1679 | H13: 百亿补贴 | I13: 云米 AI净水器小海豚2，云米·泉先 AI冷热管线机 Super 2E | J13: MR1021,MG5D-A
A14: 17 | B14: 两件套1000G+管线机2S | C14: 846750208008 | D14: S2503111808001 | E14: 1807596233986 | G14: 1599 | H14: 百亿补贴失效，产品比价，重新上链接846750208008 | I14: 云米 AI净水器小海豚2，云米·泉先AI管线机Master2S | J14: MR1021,MG6-A
A15: 14 | B15: 即热1000G | C15: 846360072018 | D15: 6923185651116 | E15: 1807240839093 | F15: 10.01.01.01.0152 | G15: 1488 | H15: 京东1439，多多1439 | I15: 云米·泉先AI即热净水器 Super Pro 1000G(升级) | J15: MR862,MG6-A
A16: 15 | B16: 即热1000G | C16: 364990106384 | D16: 6923185651116 | E16: 1455593712429 | F16: 10.01.01.01.0152 | G16: 1499 | H16: 百亿补贴,京东 1295,京东1367.28，跟价。上涨20 | I16: 云米·泉先AI即热净水器 Super Pro 1000G(升级) | J16: MR862
A17: 16 | B17: 小海豚3复合滤芯 | C17: 296967601341 | D17: 6923185657347 | E17: 1825203669118 | G17: 199
A18: 13 | B18: 两件套600G+管线机2E | C18: 480070620581 | D18: S2407170910001 | E18: 1620106386127 | G18: 1429 | H18: 百亿补贴，1429 | I18: 云米AI净水器小海豚600G+，云米·泉先 AI冷热管线机 Super 2E | J18: MR662-E,MG5D-A
A19: 11 | B19: 两件套600G+管线机2S | C19: 480070620581 | D19: S2405281401001 | E19: 1620106386127 | G19: 1349 | H19: 百亿补贴，1349,该商品平台求助率较高，不符合频道要求，请整改后报名。 | I19: 云米AI净水器小海豚600G+，云米·泉先AI管线机Master2S | J19: MR662-E,MG6-A
A20: 19 | B20: 新品管线机 冷热管线机Super2 Pro | C20: 837301408995 | D20: 6923185655794 | E20: 1813015099169 | F20: 10.01.01.04.0007 | G20: 1999 | H20: 京东1699，投诉我，我百亿下了 | I20: 云米AI冷热管线机Super2 Pro | J20: MG6D-A
A21: 20 | B21: AI净饮机Super2 | C21: 826920121377 | D21: 6923185615415 | E21: 1792670253677 | F21: 10.01.01.02.0026 | G21: 2199 | H21: 京东998，滤芯终身5折。天猫1025，滤芯终身7折。比价，需要重起链接850344043841 | I21: 云米AI净饮机Super 2 | J21: MR122R-B
A22: 21 | B22: 昆仑2E 1000G | C22: 849648457333 | D22: 6923185654254 | E22: 1810108178225 | F22: 10.01.01.01.0184 | G22: 2599 | H22: 拼多多美承1854，京东1404，天猫1519，价格表1679，我1679报名百亿试试，不行再看 | I22: 云米AI昆仑矿泉净水机 Super 2E 2500 | J22: MR10102-E
A23: 22 | B23: 小海豚600G+2支滤芯 | C23: 852932116812 | D23: S2508151538001 | E23: 1812983769340 | G23: 749

Sheet Sheet2
C4: 渠道 | D4: 责任人 | E4: 缺口原因 | F4: 本周重点进度 | G4: 下周重点规划
C5: 拼多多 | D5: 金雨 | E5: 1、GSV 1）月度目标：320万 ，达成：341.53万 ，达成率：106.7% 2）周度目标：35万，本周达成：36万，本周达成率：102% 2、出货 1）月度目标：170万，达成：200.8万 ，达成率118.14% ； 2）周度目标：30万，达成：33.6万，达成率：112%； | F5: 1. 双11复盘，小海豚3上市方案准备。 2. 小海豚600G本周销售338，环比上周380台下滑11%，日均从双11后的54台左右下滑到48台。主要影响的有推广费投入退坡，从15%逐步退至10%，销售有波动影响。 3.厨热产品百补提报：Flash烟灶套装液化气、蓝调2燃热X1重新建链接提报并上线百补。 | G5: 1. 小海豚3新品上市预售准备：商品创建，包括服务套装，滤芯套装等sku的创建和预售，百亿活动的申报。 2.双12海豚2 销售推进，恢复100台+日销。 3.拼多多26年店铺矩阵和承接商规划及推进落地。
C6: 拼多多 | D6: 金雨 | E6: 1、GSV净水 1）月度目标：320万 ，达成：284.01万 ，达成率：88.8% 2）周度目标：50万，本周达成：70万，达成率：140%； 2、GSV智能 1）月度目标：156万，达成：71万，达成率：45.5%。 2）周度目标：39万，达成：17万，达成率：24.3%。 | F6: 净水： 1.双11复盘，小海豚3上市方案准备。 2.单品链接上新增6年滤芯套装，日均销售7台，下周开始申报短期3天官补。 3.小海豚600G+管线套装受其他平台底价影响掉标需重新培养日销报名百亿。 智能： 1.已完成双十一复盘； 2.主推烟灶套装、热水器等调整链接提报并上线百补。 | G6: 净水： 1.小海豚3新品的链接创建和配套的sku创建。百亿补贴报名和预售设置。专项广告费申请； 2.小海豚600G+管线机的套装裂变，新增+前置过滤器的套装申报百亿补贴； 3.小海豚3新品上市的站内外推广方案优化。 智能： 1.完善烟灶套装sku提报上线百补； 2.蓝调2燃热重新建链提报并上线百补。
C7: 拼多多 | D7: 金雨 | E7: 1、GSV 1）月度目标：320万 ，达成：228万 ，达成率：71.3% 2）周度目标：50万，本周达成：134万，本周达成率：268% 2、出货 1）月度目标：170万，达成：120万 ，达成率71% ； 2）周度目标：50万，达成：80.4万，达成率：160%； 进度达预期，持续推进。 | F7: 1. 优化小海豚的推广创意，优化推广成本，本周投产从5逐步提升到8，在投放逐步放大的前提下。 2. 扩充产品，补充639元（600G）,699元（800G）,799元（1000G），1199元（1200G）,1499（1000G即热）都取得了良好的反馈，金额占比达到26%。 3.蓝调2PRO燃热新品上架并上线百补。 4.双11当天调整10元券只549做收割，当天销售350台+ | G7: 1. 双11复盘及小海豚销售持续推进 2. 新品小海豚3上市筹备和预算规划 3. X1电热关注评分问题重新提报百补

Sheet Sheet3
A4: 小海豚3（不包安装 | B4: https://detail.tmall.com/item.htm?id=899913391731&skuId=5985824424965 | C4: 5985824424965
A5: 小海豚3（包安装） | B5: https://detail.tmall.com/item.htm?id=899913391731&skuId=5985824424966 | C5: 5985824424966
A6: 小海豚3（包安装）+一支滤芯 | B6: https://detail.tmall.com/item.htm?id=899913391731&skuId=5985824424967 | C6: 5985824424967
A7: 小海豚3（包安装）+两支滤芯 | B7: https://detail.tmall.com/item.htm?id=899913391731&skuId=5985824424968 | C7: 5985824424968
